Workbook

Sheet DMart Board Analysis Governance
A1: Name | B1: Designation | C1: Detailed Educational Qualifications | D1: Professional Background | E1: Political Connection | F1: Negative News | G1: Comments / Analyst Insight
A2: Chandrashekhar Bhave | B2: Chairman & Independent Director | C2: M.A.; Alumnus of the 1975 IAS batch. | D2: Former SEBI Chairman and NSDL founder; credited with digitizing the Indian stock market. | E2: No (Ex-Bureaucrat) | F2: No | G2: Provides the "Regulatory Shield." His presence ensures absolute compliance with SEBI norms, crucial for an FPI-heavy stock.
A3: Anshul Asawa | B3: CEO & MD (Effective 2026) | C3: B.Tech (Mechanical), IIT Roorkee; PGDM, IIM Lucknow (1995). | D3: 30-year UNoever veteran; former Country Head (Thailand) and VP Marketing (Europe). | E3: No | F3: No | G3: The "Growth Catalyst." Hired to modernize DMart’s supply chain and digitize operations to counter the Quick Commerce threat.
A4: Ramakant Baheti | B4: Group CFO & Whole-time Director | C4: B.Com; Chartered Accountant (ICAI); 25+ years in retail finance. | D4: A founder-level executive; has been with DMart since its inception in 2000. | E4: No | F4: No | G4: The "Financial Architect." Known for the strict "Everyday Low Cost" (EDLC) model. He is the bridge between the promoter's vision and public markets.
A5: Rita Teaotia | B5: Independent Director | C5: M.A. (History), University of Lucknow; 1981-batch IAS officer. | D5: Former Commerce Secretary of India and Chairperson of FSSAI. | E5: Ex-High Ranking Civil Servant | F5: No | G5: Her expertise in food safety (FSSAI) and logistics (Ministry of Commerce) is vital for DMart’s massive grocery and private-label operations.
A6: Kalpana Unadkat | B6: Independent Director | C6: LL.B. (India); Solicitor (UK/Wales). Senior Partner at Khaitan & Co. | D6: Expert in M&A and international corporate governance; former head of Ashurst’s India practice. | E6: No | F6: No | G6: Ensures "Legal Integrity." Her role is critical for evaluating future acquisitions or joint ventures as DMart scales beyond physical stores.
A7: Harischandra M. Bharuka | B7: Independent Director | C7: B.Com; ICWA (Institute of Cost Accountants of India). | D7: Former MD of Kansai Nerolac Paints; recognized for operational turnarounds. | E7: No | F7: No | G7: Brings "Operational Efficiency." His background in high-volume manufacturing helps DMart optimize its in-house brand production and warehousing.
A8: Manjri Chandak | B8: Non-Executive Director | C8: B.Com. | D8: Representative of the Damani Family (Promoter Group). | E8: Family Connection | F8: No | G8: Acts as the "Promoter’s Pulse." Ensures that the board's decisions remain aligned with the long-term, conservative ethos of Radhakishan Damani.
A9: Elvin Machado | B9: Whole-time Director | C9: B.Com. | D9: 20+ years at DMart; lead on Real Estate & Expansion strategy. | E9: No | F9: No | G9: The "Store Builder." DMart owns most of its land/stores; Machado’s expertise in property acquisition is the engine of their low-rent advantage.

Sheet Relative Stock Performance
A1: Date | B1: Avenue Supermart | C1: NIFTY
A2: 17-02-2021 | B2: 3190 | C2: 15208.9
A3: 18-02-2021 | B3: 3092 | C3: 15118.95
A4: 19-02-2021 | B4: 3080 | C4: 14981.75
A5: 22-02-2021 | B5: 2983 | C5: 14675.7
A6: 23-02-2021 | B6: 3143 | C6: 14707.8
A7: 24-02-2021 | B7: 3124.8 | C7: 14982
A8: 25-02-2021 | B8: 3082.9 | C8: 15097.35
A9: 26-02-2021 | B9: 2960 | C9: 14529.15
A10: 44199 | B10: 2903.05 | C10: 14761.55
A11: 44230 | B11: 3089 | C11: 14919.1
A12: 44258 | B12: 3160 | C12: 15245.6
A13: 44289 | B13: 3141 | C13: 15080.75
A14: 44319 | B14: 3271 | C14: 14938.1
A15: 44411 | B15: 3190 | C15: 14956.2
A16: 44442 | B16: 3144.9 | C16: 15098.4
A17: 44472 | B17: 3155 | C17: 15174.8
A18: 44533 | B18: 3136.7 | C18: 15030.95
A19: 15-03-2021 | B19: 3114.95 | C19: 14929.5
A20: 16-03-2021 | B20: 3065 | C20: 14910.45
A21: 17-03-2021 | B21: 3001 | C21: 14721.3
A22: 18-03-2021 | B22: 3030 | C22: 14557.85
A23: 19-03-2021 | B23: 2958 | C23: 14744
A24: 22-03-2021 | B24: 2905 | C24: 14736.4
A25: 23-03-2021 | B25: 2930 | C25: 14814.75
A26: 24-03-2021 | B26: 2870 | C26: 14549.4
A27: 25-03-2021 | B27: 2796.8 | C27: 14324.9
A28: 26-03-2021 | B28: 2861 | C28: 14507.3
A29: 30-03-2021 | B29: 2830 | C29: 14845.1
A30: 31-03-2021 | B30: 2870 | C30: 14690.7
A31: 44200 | B31: 2910 | C31: 14867.35
A32: 44320 | B32: 2836.15 | C32: 14637.8
A33: 44351 | B33: 2851 | C33: 14683.5
A34: 44381 | B34: 2880 | C34: 14819.05
A35: 44412 | B35: 2932.9 | C35: 14873.8
A36: 44443 | B36: 2940 | C36: 14834.85
A37: 44534 | B37: 2821.35 | C37: 14310.8
A38: 13-04-2021 | B38: 2830 | C38: 14504.8
A39: 15-04-2021 | B39: 2929.05 | C39: 14581.45
A40: 16-04-2021 | B40: 2906.95 | C40: 14617.85
...

Sheet Finanacial Summary
A1: Particulars | B1: 44621 | C1: 44986 | D1: 45352 | E1: 45717
A2: Revenue from Operations | B2: 30976 | C2: 42840 | D2: 50789 | E2: 59358
A3: YoY Growth (%) | B3: 0.22059013 | C3: =((C2-B2)/C2) -> 0.27693744 | D3: =((D2-C2)/D2) -> 0.15651027 | E3: =((E2-D2)/E2) -> 0.14436133
A4: EBITDA | B4: =B1-B3 -> 44620.779 | C4: =C1-C3 -> 44985.723 | D4: =D1-D3 -> 45351.843 | E4: =E1-E3 -> 45716.856
A5: EBITDA Margin | B5: 0.08 | C5: 0.08 | D5: 0.08 | E5: 0.08
A6: PAT | B6: 1492 | C6: 2378 | D6: 2536 | E6: 2707
A7: PAT Growth | B7: 0.08 | C7: =((C6-B6)/C6) -> 0.372582 | D7: =((D6-C6)/D6) -> 0.062302839 | E7: =((E6-D6)/E6) -> 0.06316956
A8: EPS | B8: 23.04 | C8: 36.69 | D8: 38.97 | E8: 41.61

Sheet Shareholding Analysis
B1: 45382 | C1: 45473 | D1: 45565 | E1: 45657 | F1: 45382 | G1: 45838 | H1: 45930 | I1: 46022
A2: Promoters | B2: 0.7465 | C2: 0.7465 | D2: 0.7465 | E2: 0.7465 | F2: 0.7465 | G2: 0.7465 | H2: 0.7465 | I2: 0.7465
A4: FIIs | B4: 0.0826 | C4: 0.0922 | D4: 0.0995 | E4: 0.0896 | F4: 0.0818 | G4: 0.0825 | H4: 0.0873 | I4: 0.0889
A6: Mutual Funds | B6: 0.0729 | C6: 0.0681 | D6: 0.0595 | E6: 0.0677 | F6: 0.0763 | G6: 0.0737 | H6: 0.0684 | I6: 0.0669
A7: Banks and Insurance | B7: 0.0089 | C7: 0.0081 | D7: 0.0068 | E7: 0.0046 | F7: 0.006 | G7: 0.0079 | H7: 0.0086 | I7: 0.006
A8: Other | B8: =B9-(B6+B7) -> 0.0041 | C8: =C9-(C6+C7) -> 0.0041 | D8: =D9-(D6+D7) -> 0.0086 | E8: =E9-(E6+E7) -> 0.0091 | F8: =F9-(F6+F7) -> 0.0092 | G8: =G9-(G6+G7) -> 0.0113 | H8: =H9-(H6+H7) -> 0.0138 | I8: =I9-(I6+I7) -> 0.016
A9: DIIs | B9: 0.0859 | C9: 0.0803 | D9: 0.0749 | E9: 0.0814 | F9: 0.0915 | G9: 0.0929 | H9: 0.0908 | I9: 0.0889
A11: Resident Individuals | B11: 0.0543 | C11: 0.0507 | D11: 0.0489 | E11: 0.0517 | F11: 0.0495 | G11: 0.047 | H11: 0.0437 | I11: 0.0461
A12: Non-Resident Indians | B12: 0.0011 | C12: 0.001 | D12: 0.001 | E12: 0.001 | F12: 0.0011 | G12: 0.0011 | H12: 0.0011 | I12: 0.0011
A13: Bodies Corporate | B13: 0.0018 | C13: 0.0017 | D13: 0.0017 | E13: 0.0016 | F13: 0.0015 | G13: 0.0017 | H13: 0.0017 | I13: 0.0017
A14: Ignatius Navil Noronha | B14: 0.0196 | C14: 0.0195 | D14: 0.0195 | E14: 0.0195 | F14: 0.0194 | G14: 0.0193 | H14: 0.0193 | I14: 0.0193
A15: Others | B15: =B16-(SUM(B11:B14)) -> 0.0082 | C15: =C16-(SUM(C11:C14)) -> 0.0081 | D15: =D16-(SUM(D11:D14)) -> 0.008 | E15: =E16-(SUM(E11:E14)) -> 0.0087 | F15: =F16-(SUM(F11:F14)) -> 0.0088 | G15: =G16-(SUM(G11:G14)) -> 0.0089 | H15: =H16-(SUM(H11:H14)) -> 0.0095 | I15: =I16-(SUM(I11:I14)) -> 0.0093
A16: Total Non-Institution (Public) | B16: 0.085 | C16: 0.081 | D16: 0.0791 | E16: 0.0825 | F16: 0.0803 | G16: 0.078 | H16: 0.0753 | I16: 0.0775
A18: Grand Total | B18: 1 | C18: 1 | D18: 1 | E18: 1 | F18: 1 | G18: 1 | H18: 1 | I18: 1

Sheet Quarterly Snapshot
A1: Particulars | B1: 45382 | C1: 45473 | D1: 45565 | E1: 45657 | F1: 45747 | G1: 45838 | H1: 45930 | I1: 46022
A2: Revenue from Operations | B2: 12727 | C2: 14069 | D2: 14444 | E2: 15973 | F2: 14872 | G2: 16360 | H2: 16676 | I2: 18101
A3: QoQ Growth (%) | C3: =((C2-B2)/C2) -> 0.095387021 | D3: =((D2-C2)/D2) -> 0.025962337 | E3: =((E2-D2)/E2) -> 0.095724034 | F3: =((F2-E2)/F2) -> -0.074031737 | G3: =((G2-F2)/G2) -> 0.090953545 | H3: =((H2-G2)/H2) -> 0.018949388 | I3: =((I2-H2)/I2) -> 0.078724932
A4: Expenses | B4: 11783 | C4: 12848 | D4: 13351 | E4: 14755 | F4: 13917 | G4: 15061 | H4: 15463 | I4: 16638
A5: EBITDA | B5: =B2-B4 -> 944 | C5: =C2-C4 -> 1221 | D5: =D2-D4 -> 1093 | E5: =E2-E4 -> 1218 | F5: =F2-F4 -> 955 | G5: =G2-G4 -> 1299 | H5: =H2-H4 -> 1213 | I5: =I2-I4 -> 1463
A6: EBITDA Margin | B6: 0.07 | C6: 0.09 | D6: 0.08 | E6: 0.08 | F6: 0.06 | G6: 0.08 | H6: 0.07 | I6: 0.08
A7: (-) Depreciation | B7: 205 | C7: 193 | D7: 208 | E7: 228 | F7: 241 | G7: 232 | H7: 253 | I7: 268
A8: EBIT | B8: =B5-B7 -> 739 | C8: =C5-C7 -> 1028 | D8: =D5-D7 -> 885 | E8: =E5-E7 -> 990 | F8: =F5-F7 -> 714 | G8: =G5-G7 -> 1067 | H8: =H5-H7 -> 960 | I8: =I5-I7 -> 1195
A9: EBIT Margin | B9: =B8/B2 -> 0.05806553 | C9: =C8/C2 -> 0.073068448 | D9: =D8/D2 -> 0.061271116 | E9: =E8/E2 -> 0.061979591 | F9: =F8/F2 -> 0.048009683 | G9: =G8/G2 -> 0.065220049 | H9: =H8/H2 -> 0.057567762 | I9: =I8/I2 -> 0.066018452
A10: (-) Finance Cost | B10: 13 | C10: 16 | D10: 16 | E10: 18 | F10: 19 | G10: 29 | H10: 35 | I10: 37
A11: EBT | B11: =B8-B10 -> 726 | C11: =C8-C10 -> 1012 | D11: =D8-D10 -> 869 | E11: =E8-E10 -> 972 | F11: =F8-F10 -> 695 | G11: =G8-G10 -> 1038 | H11: =H8-H10 -> 925 | I11: =I8-I10 -> 1158
A12: (+) Other Income | B12: 38 | C12: 42 | D12: 34 | E12: 24 | F12: 25 | G12: 19 | H12: 20 | I12: 17
A13: PBT | B13: =B12+B11 -> 764 | C13: =C12+C11 -> 1054 | D13: =D12+D11 -> 903 | E13: =E12+E11 -> 996 | F13: =F12+F11 -> 720 | G13: =G12+G11 -> 1057 | H13: =H12+H11 -> 945 | I13: =I12+I11 -> 1175
A14: (-) Taxes | B14: =B13-B15 -> 201 | C14: =C13-C15 -> 280 | D14: =D13-D15 -> 244 | E14: =E13-E15 -> 272 | F14: =F13-F15 -> 169 | G14: =G13-G15 -> 284 | H14: =H13-H15 -> 260 | I14: =I13-I15 -> 319
A15: PAT | B15: 563 | C15: 774 | D15: 659 | E15: 724 | F15: 551 | G15: 773 | H15: 685 | I15: 856
A16: PAT Growth | C16: =((C15-B15)/C15) -> 0.27260982 | D16: =((D15-C15)/D15) -> -0.17450683 | E16: =((E15-D15)/E15) -> 0.089779006 | F16: =((F15-E15)/F15) -> -0.31397459 | G16: =((G15-F15)/G15) -> 0.28719276 | H16: =((H15-G15)/H15) -> -0.12846715 | I16: =((I15-H15)/I15) -> 0.19976636
A17: EPS | B17: 8.66 | C17: 11.89 | D17: 10.14 | E17: 11.12 | F17: 8.47 | G17: 11.88 | H17: 10.53 | I17: 13.15

Sheet Yearly Snapshot
A1: Particulars | B1: 42795 | C1: 43160 | D1: 43525 | E1: 43891 | F1: 44256 | G1: 44621 | H1: 44986 | I1: 45352 | J1: 45717
A2: Revenue from Operations | B2: 11898 | C2: 15033 | D2: 20005 | E2: 24870 | F2: 24143 | G2: 30976 | H2: 42840 | I2: 50789 | J2: 59358
A3: YoY Growth (%) | C3: =((C2-B2)/C2) -> 0.20854121 | D3: =((D2-C2)/D2) -> 0.24853787 | E3: =((E2-D2)/E2) -> 0.19561721 | F3: =((F2-E2)/F2) -> -0.030112248 | G3: =((G2-F2)/G2) -> 0.22059013 | H3: =((H2-G2)/H2) -> 0.27693744 | I3: =((I2-H2)/I2) -> 0.15651027 | J3: =((J2-I2)/J2) -> 0.14436133
A4: Expenses | B4: 10929 | C4: 13680 | D4: 18371 | E4: 22742 | F4: 22398 | G4: 28474 | H4: 39201 | I4: 46683 | J4: 54864
A5: EBITDA | B5: =B2-B4 -> 969 | C5: =C2-C4 -> 1353 | D5: =D2-D4 -> 1634 | E5: =E2-E4 -> 2128 | F5: =F2-F4 -> 1745 | G5: =G2-G4 -> 2502 | H5: =H2-H4 -> 3639 | I5: =I2-I4 -> 4106 | J5: =J2-J4 -> 4494
A6: EBITDA Margin | B6: 0.08 | C6: 0.09 | D6: 0.08 | E6: 0.09 | F6: 0.07 | G6: 0.08 | H6: 0.08 | I6: 0.08 | J6: 0.08
A7: (-) Depreciation | B7: 128 | C7: 159 | D7: 212 | E7: 374 | F7: 414 | G7: 498 | H7: 639 | I7: 731 | J7: 870
A8: EBIT | B8: =B5-B7 -> 841 | C8: =C5-C7 -> 1194 | D8: =D5-D7 -> 1422 | E8: =E5-E7 -> 1754 | F8: =F5-F7 -> 1331 | G8: =G5-G7 -> 2004 | H8: =H5-H7 -> 3000 | I8: =I5-I7 -> 3375 | J8: =J5-J7 -> 3624
A9: EBIT Margin | B9: =B8/B2 -> 0.070684149 | C9: =C8/C2 -> 0.079425264 | D9: =D8/D2 -> 0.071082229 | E9: =E8/E2 -> 0.070526739 | F9: =F8/F2 -> 0.055129851 | G9: =G8/G2 -> 0.064695248 | H9: =H8/H2 -> 0.070028011 | I9: =I8/I2 -> 0.066451397 | J9: =J8/J2 -> 0.06105327
A10: (-) Finance Cost | B10: 122 | C10: 60 | D10: 47 | E10: 69 | F10: 42 | G10: 54 | H10: 67 | I10: 58 | J10: 69
A11: EBT | B11: =B8-B10 -> 719 | C11: =C8-C10 -> 1134 | D11: =D8-D10 -> 1375 | E11: =E8-E10 -> 1685 | F11: =F8-F10 -> 1289 | G11: =G8-G10 -> 1950 | H11: =H8-H10 -> 2933 | I11: =I8-I10 -> 3317 | J11: =J8-J10 -> 3555
A12: (+) Other Income | B12: 28 | C12: 88 | D12: 48 | E12: 60 | F12: 194 | G12: 114 | H12: 128 | I12: 145 | J12: 117
A13: PBT | B13: =B11+B12 -> 747 | C13: =C11+C12 -> 1222 | D13: =D11+D12 -> 1423 | E13: =E11+E12 -> 1745 | F13: =F11+F12 -> 1483 | G13: =G11+G12 -> 2064 | H13: =H11+H12 -> 3061 | I13: =I11+I12 -> 3462 | J13: =J11+J12 -> 3672
A14: (-) Taxes | B14: =B13-B15 -> 268 | C14: =C13-C15 -> 416 | D14: =D13-D15 -> 521 | E14: =E13-E15 -> 444 | F14: =F13-F15 -> 384 | G14: =G13-G15 -> 572 | H14: =H13-H15 -> 683 | I14: =I13-I15 -> 926 | J14: =J13-J15 -> 965
A15: PAT | B15: 479 | C15: 806 | D15: 902 | E15: 1301 | F15: 1099 | G15: 1492 | H15: 2378 | I15: 2536 | J15: 2707
A16: PAT Growth | C16: =((C15-B15)/C15) -> 0.4057072 | D16: =((D15-C15)/D15) -> 0.10643016 | E16: =((E15-D15)/E15) -> 0.30668716 | F16: =((F15-E15)/F15) -> -0.18380346 | G16: =((G15-F15)/G15) -> 0.26340483 | H16: =((H15-G15)/H15) -> 0.372582 | I16: =((I15-H15)/I15) -> 0.062302839 | J16: =((J15-I15)/J15) -> 0.06316956
A17: EPS | B17: 7.67 | C17: 12.92 | D17: 14.46 | E17: 20.09 | F17: 16.97 | G17: 23.04 | H17: 36.69 | I17: 38.97 | J17: 41.61

Sheet Revenue Analysis
A1: Particulars | B1: 42795 | C1: 43160 | D1: 43525 | E1: 43891 | F1: 44256 | G1: 44621 | H1: 44986 | I1: 45352 | J1: 45717 | K1: 46082 | L1: 46447
A2: Revenue from Operations | B2: 11898 | C2: 15033 | D2: 20005 | E2: 24870 | F2: 24143 | G2: 30976 | H2: 42840 | I2: 50789 | J2: 59358 | K2: 68454 | L2: 80280
A3: YoY Growth (%) | C3: =((C2-B2)/C2) -> 0.20854121 | D3: =((D2-C2)/D2) -> 0.24853787 | E3: =((E2-D2)/E2) -> 0.19561721 | F3: =((F2-E2)/F2) -> -0.030112248 | G3: =((G2-F2)/G2) -> 0.22059013 | H3: =((H2-G2)/H2) -> 0.27693744 | I3: =((I2-H2)/I2) -> 0.15651027 | J3: =((J2-I2)/J2) -> 0.14436133 | ... L3: =((L2-K2)/L2) -> 0.14730942

Sheet Gross Margin Analysis
A1: Particulars | B1: 43525 | C1: 43891 | D1: 44256 | E1: 44621 | F1: 44986 | G1: 45352 | H1: 45717
A2: Revenue from Operations | B2: 20005 | C2: 24870 | D2: 24143 | E2: 30976 | F2: 42840 | G2: 50789 | H2: 59358
A3: COGS | B3: 17000.84 | C3: 21102.93 | D3: 20554.68 | E3: 26407.39 | F3: 36383.95 | G3: 43274.54 | H3: 50551.7
A4: Gross Profit | B4: =B2-B3 -> 3004.16 | C4: =C2-C3 -> 3767.07 | D4: =D2-D3 -> 3588.32 | E4: =E2-E3 -> 4568.61 | F4: =F2-F3 -> 6456.05 | G4: =G2-G3 -> 7514.46 | H4: =H2-H3 -> 8806.3
A5: Gross Margin | B5: =B4/B2 -> 0.15017046 | C5: =C4/C2 -> 0.15147045 | D5: =D4/D2 -> 0.14862776 | E5: =E4/E2 -> 0.1474887 | F5: =F4/F2 -> 0.15070145 | G5: =G4/G2 -> 0.14795448 | H5: =H4/H2 -> 0.14835911

Sheet EBITDA Margin Analysis
A1: Particulars | B1: 43525 | C1: 43891 | D1: 44256 | E1: 44621 | F1: 44986 | G1: 45352 | H1: 45717
A2: Revenue from Operations | B2: 20005 | C2: 24870 | D2: 24143 | E2: 30976 | F2: 42840 | G2: 50789 | H2: 59358
A3: EBITDA | B3: 1634 | C3: 2128 | D3: 1745 | E3: 2502 | F3: 3639 | G3: 4106 | H3: 4494
A4: EBITDA Margin | B4: 0.071082229 | C4: 0.070526739 | D4: 0.055129851 | E4: 0.064695248 | F4: 0.070028011 | G4: 0.066451397 | H4: 0.06105327
A5: EBITDA YoY Growth | B5: =('Yearly Snapshot'!D5-'Yearly Snapshot'!C5)/'Yearly Snapshot'!D5 -> 0.17197062 | C5: =('Yearly Snapshot'!E5-'Yearly Snapshot'!D5)/'Yearly Snapshot'!E5 -> 0.23214286 | D5: =('Yearly Snapshot'!F5-'Yearly Snapshot'!E5)/'Yearly Snapshot'!F5 -> -0.21948424 | E5: =('Yearly Snapshot'!G5-'Yearly Snapshot'!F5)/'Yearly Snapshot'!G5 -> 0.30255795 | F5: =('Yearly Snapshot'!H5-'Yearly Snapshot'!G5)/'Yearly Snapshot'!H5 -> 0.31244847 | G5: =('Yearly Snapshot'!I5-'Yearly Snapshot'!H5)/'Yearly Snapshot'!I5 -> 0.113736 | H5: =('Yearly Snapshot'!J5-'Yearly Snapshot'!I5)/'Yearly Snapshot'!J5 -> 0.086337339
A6: 2 per. Mov. Avg. (EBITDA Yoy Growth) | C6: =(C5+B5)/2 -> 0.20205674 | D6: =(D5+C5)/2 -> 0.0063293082 | E6: =(E5+D5)/2 -> 0.041536856 | F6: =(F5+E5)/2 -> 0.30750321 | G6: =(G5+F5)/2 -> 0.21309224 | H6: =(H5+G5)/2 -> 0.10003667

Sheet Depreciation Analysis
A1: Particulars | B1: 42795 | C1: 43160 | D1: 43525 | E1: 43891 | F1: 44256 | G1: 44621 | H1: 44986 | I1: 45352 | J1: 45717
A2: Revenue from Operations | B2: 11898 | C2: 15033 | D2: 20005 | E2: 24870 | F2: 24143 | G2: 30976 | H2: 42840 | I2: 50789 | J2: 59358
A3: YoY Growth (%) | C3: =((C2-B2)/C2) -> 0.20854121 | D3: =((D2-C2)/D2) -> 0.24853787 | E3: =((E2-D2)/E2) -> 0.19561721 | F3: =((F2-E2)/F2) -> -0.030112248 | G3: =((G2-F2)/G2) -> 0.22059013 | H3: =((H2-G2)/H2) -> 0.27693744 | I3: =((I2-H2)/I2) -> 0.15651027 | J3: =((J2-I2)/J2) -> 0.14436133
A5: Fixed Assets | B5: 3696.82 | C5: 3423.09 | D5: 4650.87 | E5: 6189.09 | F5: 7918.33 | G5: 10288.4 | H5: 12059.65 | I5: 14233.51 | J5: 17190.91
A6: Fixed Assets (%) Growth | C6: =(C5-B5)/C5 -> -0.079965762 | D6: =(D5-C5)/D5 -> 0.26398932 | E6: =(E5-D5)/E5 -> 0.24853735 | F6: =(F5-E5)/F5 -> 0.21838443 | G6: =(G5-F5)/G5 -> 0.23036332 | H6: =(H5-G5)/H5 -> 0.14687408 | I6: =(I5-H5)/I5 -> 0.15272832 | J6: =(J5-I5)/J5 -> 0.17203278
A8: Fixed Assets as a % of Rev. | B8: =B5/B2 -> 0.31070936 | C8: =C5/C2 -> 0.22770505 | D8: =D5/D2 -> 0.23248538 | E8: =E5/E2 -> 0.24885766 | F8: =F5/F2 -> 0.32797623 | G8: =G5/G2 -> 0.33214101 | H8: =H5/H2 -> 0.28150444 | I8: =I5/I2 -> 0.28024789 | J8: =J5/J2 -> 0.28961404
A10: Depreciation | B10: 128 | C10: 159 | D10: 212 | E10: 374 | F10: 414 | G10: 498 | H10: 639 | I10: 731 | J10: 870
A11: Depreciation (%) Growth | C11: =(C10-B10)/C10 -> 0.19496855 | D11: =(D10-C10)/D10 -> 0.25 | E11: =(E10-D10)/E10 -> 0.43315508 | F11: =(F10-E10)/F10 -> 0.096618357 | G11: =(G10-F10)/G10 -> 0.1686747 | H11: =(H10-G10)/H10 -> 0.22065728 | I11: =(I10-H10)/I10 -> 0.12585499 | J11: =(J10-I10)/J10 -> 0.15977011
A13: Depreciation as a % of Rev. | B13: =B10/B2 -> 0.010758111 | C13: =C10/C2 -> 0.010576731 | D13: =D10/D2 -> 0.010597351 | E13: =E10/E2 -> 0.015038199 | F13: =F10/F2 -> 0.017147828 | G13: =G10/G2 -> 0.016076963 | H13: =H10/H2 -> 0.014915966 | I13: =I10/I2 -> 0.01439288 | J13: =J10/J2 -> 0.014656828
A14: Depreciation as a % of Fixed Assets | B14: =B10/B5 -> 0.034624353 | C14: =C10/C5 -> 0.046449261 | D14: =D10/D5 -> 0.045582869 | E14: =E10/E5 -> 0.060428916 | F14: =F10/F5 -> 0.052283752 | G14: =G10/G5 -> 0.048404028 | H14: =H10/H5 -> 0.052986612 | I14: =I10/I5 -> 0.051357676 | J14: =J10/J5 -> 0.050608141
A16: Gross Block | B16: 2766.21 | C16: 3661.09 | D16: 4857.55 | E16: 5930.28 | F16: 7048.44 | G16: 9205.34 | H16: 11598.71 | I16: 14139.16 | J16: 17304.18
A17: Accumulated Depreciation | B17: 222.27 | C17: 385.08 | D17: 583.52 | E17: 822.92 | F17: 1109.94 | G17: 1434.88 | H17: 1873.1 | I17: 2379.97 | J17: 2954.35
A18: Net Block | B18: =B16-B17 -> 2543.94 | C18: =C16-C17 -> 3276.01 | D18: =D16-D17 -> 4274.03 | E18: =E16-E17 -> 5107.36 | F18: =F16-F17 -> 5938.5 | G18: =G16-G17 -> 7770.46 | H18: =H16-H17 -> 9725.61 | I18: =I16-I17 -> 11759.19 | J18: =J16-J17 -> 14349.83
A19: Depreciation of the year | B19: 125.95 | C19: 164.29 | D19: 203.02 | E19: 261.87 | F19: 289.23 | G19: 339.98 | H19: 459.59 | I19: 533.65 | J19: 632.73
A20: % Dep. | B20: =B17/B16 -> 0.080351817 | C20: =C17/C16 -> 0.10518179 | D20: =D17/D16 -> 0.1201264 | E20: =E17/E16 -> 0.13876579 | F20: =F17/F16 -> 0.15747314 | G20: =G17/G16 -> 0.15587474 | H20: =H17/H16 -> 0.1614921 | I20: =I17/I16 -> 0.16832471 | J20: =J17/J16 -> 0.17073042
A22: Avgerage Life of Asset | B22: =B16/B19 -> 21.962763 | C22: =C16/C19 -> 22.284314 | D22: =D16/D19 -> 23.92646 | E22: =E16/E19 -> 22.645893 | F22: =F16/F19 -> 24.369671 | G22: =G16/G19 -> 27.076122 | H22: =H16/H19 -> 25.237081 | I22: =I16/I19 -> 26.495193 | J22: =J16/J19 -> 27.348442
A23: Average Age of Asset | B23: =B17/B19 -> 1.7647479 | C23: =C17/C19 -> 2.3439041 | D23: =D17/D19 -> 2.8741996 | E23: =E17/E19 -> 3.1424753 | F23: =F17/F19 -> 3.8375687 | G23: =G17/G19 -> 4.2204836 | H23: =H17/H19 -> 4.0755891 | I23: =I17/I19 -> 4.4597957 | J23: =J17/J19 -> 4.6692112
A25: Change in Revenue | C25: =C2-B2 -> 3135 | D25: =D2-C2 -> 4972 | E25: =E2-D2 -> 4865 | F25: =F2-E2 -> -727 | G25: =G2-F2 -> 6833 | H25: =H2-G2 -> 11864 | I25: =I2-H2 -> 7949 | J25: =J2-I2 -> 8569
A26: Change in Fixed Assets | C26: =C5-B5 -> -273.73 | D26: =D5-C5 -> 1227.78 | E26: =E5-D5 -> 1538.22 | F26: =F5-E5 -> 1729.24 | G26: =G5-F5 -> 2370.07 | H26: =H5-G5 -> 1771.25 | I26: =I5-H5 -> 2173.86 | J26: =J5-I5 -> 2957.4
A28: Change in Revenue / Change in Fixed Assets | C28: =C25/C26 -> -11.452892 | D28: =D25/D26 -> 4.0495854 | E28: =E25/E26 -> 3.1627466 | F28: =F25/F26 -> -0.42041591 | G28: =G25/G26 -> 2.8830372 | H28: =H25/H26 -> 6.6980946 | I28: =I25/I26 -> 3.6566292 | J28: =J25/J26 -> 2.8974775

Sheet EBIT Margin Analysis
A1: Particulars | B1: 42795 | C1: 43160 | D1: 43525 | E1: 43891 | F1: 44256 | G1: 44621 | H1: 44986 | I1: 45352 | J1: 45717
A2: Revenue from Operations | B2: 11898 | C2: 15033 | D2: 20005 | E2: 24870 | F2: 24143 | G2: 30976 | H2: 42840 | I2: 50789 | J2: 59358
A3: EBIT | B3: 841 | C3: 1194 | D3: 1422 | E3: 1754 | F3: 1331 | G3: 2004 | H3: 3000 | I3: 3375 | J3: 3624
A4: EBIT Margin | B4: 0.070684149 | C4: 0.079425264 | D4: 0.071082229 | E4: 0.070526739 | F4: 0.055129851 | G4: 0.064695248 | H4: 0.070028011 | I4: 0.066451397 | J4: 0.06105327

Sheet Peers-Quarterly
B1: Reliance Retail
A2: Particulars | B2: 45382 | C2: 45473 | D2: 45565 | E2: 45657 | F2: 45747 | G2: 45838 | H2: 45930 | I2: 46022
A3: Revenue from Operations | B3: 76683 | C3: 75630 | D3: 76325 | E3: 90351 | F3: 88637 | G3: 84172 | H3: 90544 | I3: 97912
A4: QoQ Growth (%) | C4: =((C3-B3)/C3) -> -0.013923046 | D4: =((D3-C3)/D3) -> 0.0091057976 | E4: =((E3-D3)/E3) -> 0.15523901 | F4: =((F3-E3)/F3) -> -0.019337297 | G4: =((G3-F3)/G3) -> -0.053046144 | H4: =((H3-G3)/H3) -> 0.070374624 | I4: =((I3-H3)/I3) -> 0.075251246
A5: Expenses | B5: =B3-B6 -> 70854 | C5: =C3-C6 -> 69958 | D5: =D3-D6 -> 70464 | E5: =E3-E6 -> 83511 | F5: =F3-F6 -> 81916 | G5: =G3-G6 -> 77791 | H5: =H3-H6 -> 83727 | I5: =I3-I6 -> 90997
A6: EBITDA | B6: 5829 | C6: 5672 | D6: 5861 | E6: 6840 | F6: 6721 | G6: 6381 | H6: 6817 | I6: 6915
A7: EBITDA Margin | B7: =B6/B3 -> 0.07601424 | C7: =C6/C3 -> 0.074996694 | D7: =D6/D3 -> 0.076790043 | E7: =E6/E3 -> 0.075704751 | F7: =F6/F3 -> 0.075826122 | G7: =G6/G3 -> 0.075809058 | H7: =H6/H3 -> 0.075289362 | I7: =I6/I3 -> 0.070624643
A8: (-) Depreciation | B8: =B6-B9 -> 1457 | C8: =C6-C9 -> 1670 | D8: =D6-D9 -> 1429 | E8: =E6-E9 -> 1518 | F8: =F6-F9 -> 1407 | G8: =G6-G9 -> 1515 | H8: =H6-H9 -> 1548 | I8: =I6-I9 -> 1575
A9: EBIT | B9: 4372 | C9: 4002 | D9: 4432 | E9: 5322 | F9: 5314 | G9: 4866 | H9: 5269 | I9: 5340
A10: EBIT Margin | B10: =B9/B3 -> 0.057013941 | C10: =C9/C3 -> 0.05291551 | D10: =D9/D3 -> 0.058067475 | E10: =E9/E3 -> 0.058903609 | F10: =F9/F3 -> 0.05995239 | G10: =G9/G3 -> 0.057810198 | H10: =H9/H3 -> 0.058192702 | I10: =I9/I3 -> 0.05453877

Sheet Peers-Yearly
B1: Reliance Retail
A2: Particulars | B2: 44256 | C2: 44621 | D2: 44986 | E2: 45352 | F2: 45717
A3: Revenue from Operations | B3: 136911 | C3: 170133 | D3: 223653 | E3: 258388 | F3: 271012
A4: YoY Growth (%) | C4: =(C3-B3)/C3 -> 0.19527076 | D4: =(D3-C3)/D3 -> 0.23929927 | E4: =(E3-D3)/E3 -> 0.13442962 | F4: =(F3-E3)/F3 -> 0.046580963
A5: COGS | B5: 117940.34 | C5: 147485.2 | D5: 192986 | E5: 223306 | F5: 233997
A6: Gross Profit | B6: =B3-B5 -> 18970.66 | C6: =C3-C5 -> 22647.8 | D6: =D3-D5 -> 30667 | E6: =E3-E5 -> 35082 | F6: =F3-F5 -> 37015
A7: Gross Profit Margin | B7: =B6/B3 -> 0.13856199 | C7: =C6/C3 -> 0.13311821 | D7: =D6/D3 -> 0.13711866 | E7: =E6/E3 -> 0.13577256 | F7: =F6/F3 -> 0.13658067
A8: Other Expenses | B8: 10843.66 | C8: 12314.8 | D8: 14477 | E8: 14831 | F8: 14657
A9: EBITDA | B9: =B3-(B8+B5) -> 8127 | C9: =C3-(C8+C5) -> 10333 | D9: =D3-(D8+D5) -> 16190 | E9: =E3-(E8+E5) -> 20251 | F9: =F3-(F8+F5) -> 22358
A10: EBITDA Margin | B10: =B9/B3 -> 0.05935973 | C10: =C9/C3 -> 0.060734837 | D10: =D9/D3 -> 0.072388924 | E10: =E9/E3 -> 0.078374383 | F10: =F9/F3 -> 0.082498192
A11: (-) Depreciation | B11: 1462 | C11: 1794 | D11: 2989 | E11: 4035 | F11: 4519
A12: EBIT | B12: =B9-B11 -> 6665 | C12: =C9-C11 -> 8539 | D12: =D9-D11 -> 13201 | E12: =E9-E11 -> 16216 | F12: =F9-F11 -> 17839
A13: EBIT Margin | B13: =B12/B3 -> 0.04868126 | C13: =C12/C3 -> 0.050190145 | D13: =D12/D3 -> 0.059024471 | E13: =E12/E3 -> 0.062758332 | F13: =F12/F3 -> 0.065823654
A14: (-) Finance Cost | B14: 694 | C14: 1986 | D14: 3923 | E14: 4462 | F14: 4725
A15: EBT | B15: =B12-B14 -> 5971 | C15: =C12-C14 -> 6553 | D15: =D12-D14 -> 9278 | E15: =E12-E14 -> 11754 | F15: =F12-F14 -> 13114
A16: (+) Other Income | B16: 296 | C16: 22 | D16: 110 | E16: 86 | F16: 215
A17: PBT | B17: =B15+B16 -> 6267 | C17: =C15+C16 -> 6575 | D17: =D15+D16 -> 9388 | E17: =E15+E16 -> 11840 | F17: =F15+F16 -> 13329
A18: (-) Taxes | B18: =B17-B19 -> 1668 | C18: =C17-C19 -> 1637 | D18: =D17-D19 -> 2343 | E18: =E17-E19 -> 2965 | F18: =F17-F19 -> 3356
A19: PAT | B19: 4599 | C19: 4938 | D19: 7045 | E19: 8875 | F19: 9973
A20: PAT Growth | C20: =(C19-B19)/C19 -> 0.068651276 | D20: =(D19-C19)/D19 -> 0.29907736 | E20: =(E19-D19)/E19 -> 0.20619718 | F20: =(F19-E19)/F19 -> 0.11009726
A21: EPS | B21: 4.93 | C21: 5.3 | D21: 7.55 | E21: 10.86 | F21: 9.94
B23: Vishal Mega Mart
A24: Particulars | B24: Mar, 2021 | C24: Mar, 2022 | D24: Mar, 2023 | E24: Mar, 2024 | F24: Mar 2025
A25: Revenue from Operations | B25: 4452.44 | C25: 5588.51 | D25: 7586.04 | E25: 8911.95 | F25: 10716.34
A26: YoY Growth (%) | C26: =(C25-B25)/C25 -> 0.20328674 | D26: =(D25-C25)/D25 -> 0.26331657 | E26: =(E25-D25)/E25 -> 0.14877889 | F26: =(F25-E25)/F25 -> 0.16837745
A27: COGS | B27: 3225.81 | C27: 4014.61 | D27: 5526.33 | E27: 6446.06 | F27: 7663.62
A28: Gross Profit | B28: =B25-B27 -> 1226.63 | C28: =C25-C27 -> 1573.9 | D28: =D25-D27 -> 2059.71 | E28: =E25-E27 -> 2465.89 | F28: =F25-F27 -> 3052.72
A29: Gross Profit Margin | B29: =B28/B25 -> 0.27549613 | C29: =C28/C25 -> 0.28163142 | D29: =D28/D25 -> 0.2715132 | E29: =E28/E25 -> 0.27669478 | F29: =F28/F25 -> 0.28486592
A30: Other Expenses | B30: 616.92 | C30: 770.23 | D30: 1039.19 | E30: 1217.3 | F30: 1522.54
A31: EBITDA | B31: =B25-(B30+B27) -> 609.71 | C31: =C25-(C30+C27) -> 803.67 | D31: =D25-(D30+D27) -> 1020.52 | E31: =E25-(E30+E27) -> 1248.59 | F31: =F25-(F30+F27) -> 1530.18
A32: EBITDA Margin | B32: =B31/B25 -> 0.1369384 | C32: =C31/C25 -> 0.14380756 | D32: =D31/D25 -> 0.13452605 | E32: =E31/E25 -> 0.1401029 | F32: =F31/F25 -> 0.14278942
A33: (-) Depreciation | B33: 346.14 | C33: 405.56 | D33: 461.44 | E33: 517.29 | F33: 590.23
A34: EBIT | B34: =B31-B33 -> 263.57 | C34: =C31-C33 -> 398.11 | D34: =D31-D33 -> 559.08 | E34: =E31-E33 -> 731.3 | F34: =F31-F33 -> 939.95
A35: EBIT Margin | B35: =B34/B25 -> 0.059196755 | C35: =C34/C25 -> 0.071237235 | D35: =D34/D25 -> 0.07369853 | E35: =E34/E25 -> 0.08205836 | F35: =F34/F25 -> 0.087711849
A36: (-) Finance Cost | B36: 216.61 | C36: 193.8 | D36: 161.4 | E36: 143.53 | F36: 149.2
A37: EBT | B37: =B34-B36 -> 46.96 | C37: =C34-C36 -> 204.31 | D37: =D34-D36 -> 397.68 | E37: =E34-E36 -> 587.77 | F37: =F34-F36 -> 790.75
A38: (+) Other Income | B38: 116.39 | C38: 65.33 | D38: 32.86 | E38: 33.18 | F38: 58.55
A39: PBT | B39: =B37+B38 -> 163.35 | C39: =C37+C38 -> 269.64 | D39: =D37+D38 -> 430.54 | E39: =E37+E38 -> 620.95 | F39: =F37+F38 -> 849.3
A40: (-) Taxes | B40: 44.76 | C40: 66.88 | D40: 109.26 | E40: 159.02 | F40: 217.32
A41: PAT | B41: =B39-B40 -> 118.59 | C41: =C39-C40 -> 202.76 | D41: =D39-D40 -> 321.28 | E41: =E39-E40 -> 461.93 | F41: =F39-F40 -> 631.98
...

Sheet Balance Sheet
A1: Particulars | B1: 42795 | C1: 43160 | D1: 43525 | E1: 43891 | F1: 44256 | G1: 44621 | H1: 44986 | I1: 45352 | J1: 45717
A2: Equity Capital | B2: 624.08 | C2: 624.08 | D2: 624.08 | E2: 647.77 | F2: 647.77 | G2: 647.77 | H2: 648.26 | I2: 650.73 | J2: 650.73
A3: Reserves | B3: 3217.7 | C3: 4044.97 | D3: 4963.37 | E3: 10431.97 | F3: 11535.94 | G3: 13029.87 | H3: 15430.44 | I3: 18047.09 | J3: 20777.03
A4: Borrowings | B4: =980.92+138.84 -> 1119.76 | C4: =246+7.25 -> 253.25 | D4: 429.82 | E4: 299.19 | F4: 392.71 | G4: 646.94 | H4: 642.98 | I4: 592.16 | J4: 819.62
A5: Trade Payables | B5: 260.66 | C5: =1.17+316.11 -> 317.28 | D5: 463.27 | E5: 433.45 | F5: 578.13 | G5: 589.2 | H5: 753.79 | I5: 984.81 | J5: 1070.81
A6: Other Liabilities | B6: =B7-(SUM(B2:B5)) -> 597.15 | C6: =C7-(SUM(C2:C5)) -> 372.89 | D6: =D7-(SUM(D2:D5)) -> 525.18 | E6: =E7-(SUM(E2:E5)) -> 264.07 | F6: =F7-(SUM(F2:F5)) -> 501.42 | G6: =G7-(SUM(G2:G5)) -> 558.86 | H6: =H7-(SUM(H2:H5)) -> 630.82 | I6: =I7-(SUM(I2:I5)) -> 902.41 | J6: =J7-(SUM(J2:J5)) -> 1002.1 | M6: 42795 | N6: 43160 | O6: 43525 | P6: 43891 | Q6: 44256 | R6: 44621 | S6: 44986 | T6: 45352 | U6: 45717
A7: Total Liabilities | B7: 5819.35 | C7: 5612.47 | D7: 7005.72 | E7: 12076.45 | F7: 13655.97 | G7: 15472.64 | H7: 18106.29 | I7: 21177.2 | J7: 24320.29 | L7: Current Liabilities | M7: 944.35 | N7: 685.95 | O7: 1226.92 | P7: 725.8 | Q7: 1105.77 | R7: 1218.29 | S7: 1467.01 | T7: 1979.14 | U7: 2212.16
L8: Capital Employed | M8: =B19-M7 -> 4875 | N8: =C19-N7 -> 4926.52 | O8: =D19-O7 -> 5778.8 | P8: =E19-P7 -> 11350.65 | Q8: =F19-Q7 -> 12550.2 | R8: =G19-R7 -> 14254.35 | S8: =H19-S7 -> 16639.28 | T8: =I19-T7 -> 19198.06 | U8: =J19-U7 -> 22108.13
A9: Fixed Assets | B9: 2543.93 | C9: 3276.01 | D9: 4274.03 | E9: 5107.36 | F9: 5938.5 | G9: 7770.46 | H9: 9725.61 | I9: 11759.19 | J9: 14349.83
A10: CWIP | B10: 152.89 | C10: 147.07 | D10: 376.84 | E10: 364.4 | F10: 1019.59 | G10: 1129.34 | H10: 829.16 | I10: 935.22 | J10: 1099.35
A11: Right-of-Use Assets | B11: - | C11: - | D11: - | E11: 717.33 | F11: 960.24 | G11: 1388.65 | H11: 1388.65 | I11: 1539.1 | J11: 1741.73 | M11: 42795 | N11: 43160 | O11: 43525 | P11: 43891 | Q11: 44256 | R11: 44621 | S11: 44986 | T11: 45352 | U11: 45717
A12: Other Non-Current Assets | B12: 6.44 | C12: =78.27+29.36 -> 107.63 | D12: 126.34 | E12: 123.34 | F12: 110.06 | G12: 100.91 | H12: 109.99 | I12: 116.71 | J12: 114.9 | L12: Total Shareholders' Equity | M12: =B2+B3 -> 3841.78 | N12: =C2+C3 -> 4669.05 | O12: =D2+D3 -> 5587.45 | P12: =E2+E3 -> 11079.74 | Q12: =F2+F3 -> 12183.71 | R12: =G2+G3 -> 13677.64 | S12: =H2+H3 -> 16078.7 | T12: =I2+I3 -> 18697.82 | U12: =J2+J3 -> 21427.76
A13: Investments | B13: 4.16 | C13: 68.18 | D13: 16.53 | E13: 14.68 | F13: 2.95 | G13: 5.94 | H13: 202.2 | I13: 106.67 | J13: 3.26
A14: Inventory | B14: 947.9 | C14: 1163.45 | D14: 1608.65 | E14: 1947.4 | F14: 2248.28 | G14: 2742.66 | H14: 3243.48 | I14: 3927.23 | J14: 5044.37
A15: Trade Receivables | B15: 21 | C15: 33.52 | D15: 64.37 | E15: 19.55 | F15: 43.58 | G15: 66.89 | H15: 62.16 | I15: 166.37 | J15: 153.79
A16: Cash & Bank | B16: =32.92+1851.35 -> 1884.27 | C16: =67.45+492.73 -> 560.18 | D16: 219.07 | E16: 107.88 | F16: 1445.58 | G16: 298.58 | H16: 1408.33 | I16: 638.18 | J16: 358.2
A17: Other Financial Assets | B17: =74.14+37.95 -> 112.09 | C17: =77.5+42.39 -> 119.89 | D17: 90.84 | E17: 3231.73 | F17: 1277.19 | G17: 1390.16 | H17: 425.32 | I17: 1363.25 | J17: 696.48
A18: Other Assets | B18: =B19-(SUM(B9:B17)) -> 146.67 | C18: =C19-(SUM(C9:C17)) -> 136.54 | D18: =D19-(SUM(D9:D17)) -> 229.05 | E18: =E19-(SUM(E9:E17)) -> 442.78 | F18: =F19-(SUM(F9:F17)) -> 610 | G18: =G19-(SUM(G9:G17)) -> 579.05 | H18: =H19-(SUM(H9:H17)) -> 711.39 | I18: =I19-(SUM(I9:I17)) -> 625.28 | J18: =J19-(SUM(J9:J17)) -> 758.38 | M18: 42795 | N18: 43160 | O18: 43525 | P18: 43891 | Q18: 44256 | R18: 44621 | S18: 44986 | T18: 45352 | U18: 45717
A19: Total Assets | B19: 5819.35 | C19: 5612.47 | D19: 7005.72 | E19: 12076.45 | F19: 13655.97 | G19: 15472.64 | H19: 18106.29 | I19: 21177.2 | J19: 24320.29 | L19: Current Assets | M19: 2978.6 | N19: 1972.2 | O19: 2082.58 | P19: 2347.67 | Q19: 4061.13 | R19: 3442.85 | S19: 5448.39 | T19: 6202.03 | U19: 6392.2
A22: Particulars | B22: 42795 | C22: 43160 | D22: 43525 | E22: 43891 | F22: 44256 | G22: 44621 | H22: 44986 | I22: 45352 | J22: 45717
A23: Equity Capital | B23: =B2/$B$19 -> 0.10724222 | C23: =C2/$C$19 -> 0.11119525 | D23: =D2/$D$19 -> 0.089081493 | E23: =E2/$E$19 -> 0.053639108 | F23: =F2/$F$19 -> 0.047434931 | G23: =G2/$G$19 -> 0.041865512 | H23: =H2/$H$19 -> 0.035803028 | I23: =I2/$I$19 -> 0.030727858 | J23: =J2/$J$19 -> 0.026756671
A24: Reserves | B24: =B3/$B$19 -> 0.55293117 | C24: =C3/$C$19 -> 0.7207112 | D24: =D3/$D$19 -> 0.70847393 | E24: =E3/$E$19 -> 0.86382753 | F24: =F3/$F$19 -> 0.84475435 | G24: =G3/$G$19 -> 0.84212326 | H24: =H3/$H$19 -> 0.85221434 | I24: =I3/$I$19 -> 0.85219434 | J24: =J3/$J$19 -> 0.85430848
A25: Borrowings | B25: =B4/$B$19 -> 0.19242012 | C25: =C4/$C$19 -> 0.045122736 | D25: =D4/$D$19 -> 0.061352723 | E25: =E4/$E$19 -> 0.024774665 | F25: =F4/$F$19 -> 0.028757386 | G25: =G4/$G$19 -> 0.041811869 | H25: =H4/$H$19 -> 0.035511416 | I25: =I4/$I$19 -> 0.027962148 | J25: =J4/$J$19 -> 0.033701078
A26: Trade Payables | B26: =B5/$B$19 -> 0.044791944 | C26: =C5/$C$19 -> 0.05653126 | D26: =D5/$D$19 -> 0.066127393 | E26: =E5/$E$19 -> 0.03589217 | F26: =F5/$F$19 -> 0.04233533 | G26: =G5/$G$19 -> 0.038080121 | H26: =H5/$H$19 -> 0.041631389 | I26: =I5/$I$19 -> 0.046503315 | J26: =J5/$J$19 -> 0.044029491
A27: Other Liabilities | B27: =B6/$B$19 -> 0.10261455 | C27: =C6/$C$19 -> 0.066439553 | D27: =D6/$D$19 -> 0.074964458 | E27: =E6/$E$19 -> 0.021866525 | F27: =F6/$F$19 -> 0.036718007 | G27: =G6/$G$19 -> 0.03611924 | H27: =H6/$H$19 -> 0.034839826 | I27: =I6/$I$19 -> 0.042612338 | J27: =J6/$J$19 -> 0.041204278
A28: Total Liabilities | B28: =B7/$B$19 -> 1 | C28: =C7/$C$19 -> 1 | D28: =D7/$D$19 -> 1 | E28: =E7/$E$19 -> 1 | F28: =F7/$F$19 -> 1 | G28: =G7/$G$19 -> 1 | H28: =H7/$H$19 -> 1 | I28: =I7/$I$19 -> 1 | J28: =J7/$J$19 -> 1
A30: Fixed Assets | B30: =B9/$B$19 -> 0.4371502 | C30: =C9/$C$19 -> 0.58370201 | D30: =D9/$D$19 -> 0.61007719 | E30: =E9/$E$19 -> 0.42291899 | F30: =F9/$F$19 -> 0.43486475 | G30: =G9/$G$19 -> 0.50220648 | H30: =H9/$H$19 -> 0.53713986 | I30: =I9/$I$19 -> 0.55527596 | J30: =J9/$J$19 -> 0.59003532
A31: CWIP | B31: =B10/$B$19 -> 0.026272694 | C31: =C10/$C$19 -> 0.026204149 | D31: =D10/$D$19 -> 0.053790331 | E31: =E10/$E$19 -> 0.03017443 | F31: =F10/$F$19 -> 0.074662583 | G31: =G10/$G$19 -> 0.072989483 | H31: =H10/$H$19 -> 0.045794031 | I31: =I10/$I$19 -> 0.044161646 | J31: =J10/$J$19 -> 0.045202997
A32: Right-of-Use Assets | B32: - | C32: - | D32: - | E32: =E11/$E$19 -> 0.059399078 | F32: =F11/$F$19 -> 0.070316499 | G32: =G11/$G$19 -> 0.089748744 | H32: =H11/$H$19 -> 0.076694342 | I32: =I11/$I$19 -> 0.072677219 | J32: =J11/$J$19 -> 0.071616334
A33: Other Non-Current Assets | B33: =B12/$B$19 -> 0.0011066528 | C33: =C12/$C$19 -> 0.01917694 | D33: =D12/$D$19 -> 0.018033835 | E33: =E12/$E$19 -> 0.010213266 | F33: =F12/$F$19 -> 0.0080594787 | G33: =G12/$G$19 -> 0.0065218347 | H33: =H12/$H$19 -> 0.0060746845 | I33: =I12/$I$19 -> 0.0055111157 | J33: =J12/$J$19 -> 0.0047244502
A34: Investments | B34: =B13/$B$19 -> 0.00071485647 | C34: =C13/$C$19 -> 0.012147949 | D34: =D13/$D$19 -> 0.0023595005 | E34: =E13/$E$19 -> 0.001215589 | F34: =F13/$F$19 -> 0.00021602274 | G34: =G13/$G$19 -> 0.00038390346 | H34: =H13/$H$19 -> 0.01116739 | I34: =I13/$I$19 -> 0.0050370209 | J34: =J13/$J$19 -> 0.00013404445
A35: Inventory | B35: =B14/$B$19 -> 0.16288761 | C35: =C14/$C$19 -> 0.20729732 | D35: =D14/$D$19 -> 0.22961951 | E35: =E14/$E$19 -> 0.161256 | F35: =F14/$F$19 -> 0.16463715 | G35: =G14/$G$19 -> 0.1772587 | H35: =H14/$H$19 -> 0.17913554 | I35: =I14/$I$19 -> 0.18544614 | J35: =J14/$J$19 -> 0.20741406
A36: Trade Receivables | B36: =B15/$B$19 -> 0.0036086505 | C36: =C15/$C$19 -> 0.005972415 | D36: =D15/$D$19 -> 0.0091882062 | E36: =E15/$E$19 -> 0.0016188532 | F36: =F15/$F$19 -> 0.0031912782 | G36: =G15/$G$19 -> 0.0043231149 | H36: =H15/$H$19 -> 0.0034330611 | I36: =I15/$I$19 -> 0.0078560905 | J36: =J15/$J$19 -> 0.0063235266
A37: Cash & Bank | B37: =B16/$B$19 -> 0.32379389 | C37: =C16/$C$19 -> 0.099809888 | D37: =D16/$D$19 -> 0.031270162 | E37: =E16/$E$19 -> 0.0089330888 | F37: =F16/$F$19 -> 0.105857 | G37: =G16/$G$19 -> 0.019297289 | H37: =H16/$H$19 -> 0.077781257 | I37: =I16/$I$19 -> 0.03013524 | J37: =J16/$J$19 -> 0.014728443
A38: Other Financial Assets | B38: =B17/$B$19 -> 0.019261601 | C38: =C17/$C$19 -> 0.021361361 | D38: =D17/$D$19 -> 0.012966547 | E38: =E17/$E$19 -> 0.26760596 | F38: =F17/$F$19 -> 0.093526128 | G38: =G17/$G$19 -> 0.089846335 | H38: =H17/$H$19 -> 0.023490179 | I38: =I17/$I$19 -> 0.064373477 | J38: =J17/$J$19 -> 0.028637816
A39: Other Assets | B39: =B18/$B$19 -> 0.025203846 | C39: =C18/$C$19 -> 0.02432797 | D39: =D18/$D$19 -> 0.032694712 | E39: =E18/$E$19 -> 0.036664748 | F39: =F18/$F$19 -> 0.044669108 | G39: =G18/$G$19 -> 0.037424124 | H39: =H18/$H$19 -> 0.039289661 | I39: =I18/$I$19 -> 0.029526094 | J39: =J18/$J$19 -> 0.031183016
A40: Total Assets | B40: 1 | C40: 1 | D40: 1 | E40: 1 | F40: 1 | G40: 1 | H40: 1 | I40: 1 | J40: 1

Sheet Fixed Asset Analysis
A1: Particulars | B1: 42795 | C1: 43160 | D1: 43525 | E1: 43891 | F1: 44256 | G1: 44621 | H1: 44986 | I1: 45352 | J1: 45717
A2: Land | B2: 1043.98 | C2: 1438.26 | D2: 2028.18 | E2: 2262.94 | F2: 2846.66 | G2: 3691.13 | H2: 4568.9 | I2: 5843.72 | J2: 7528.77
A3: Buildings | B3: 1354.75 | C3: 1718.16 | D3: 2115.98 | E3: 2712.27 | F3: 3023.52 | G3: 3942.02 | H3: 5028.88 | I3: 5803.15 | J3: 6615.8
A4: Plant & Equipment | B4: 88.09 | C4: 123.79 | D4: 190.9 | E4: 272.29 | F4: 343.82 | G4: 462.67 | H4: 614.71 | I4: 821.35 | J4: 1086.09
A5: Furniture & Fixtures | B5: 108.04 | C5: 140.47 | D5: 205.65 | E5: 268.36 | F5: 333.25 | G5: 443.39 | H5: 541.86 | I5: 660.84 | J5: 835.2
A6: Vehicles | B6: 6.17 | C6: 2.21 | D6: 3.01 | E6: 3.57 | F6: 3.58 | G6: 3.44 | H6: 14.78 | I6: 17.32 | J6: 6.38
A7: Other Fixed Assets | B7: =B8-(SUM(B2:B6)) -> 165.18 | C7: =C8-(SUM(C2:C6)) -> 238.21 | D7: =D8-(SUM(D2:D6)) -> 313.83 | E7: =E8-(SUM(E2:E6)) -> 410.85 | F7: =F8-(SUM(F2:F6)) -> 497.61 | G7: =G8-(SUM(G2:G6)) -> 662.69 | H7: =H8-(SUM(H2:H6)) -> 829.58 | I7: =I8-(SUM(I2:I6)) -> 992.78 | J7: =J8-(SUM(J2:J6)) -> 1231.94
A8: Gross Block | B8: 2766.21 | C8: 3661.1 | D8: 4857.55 | E8: 5930.28 | F8: 7048.44 | G8: 9205.34 | H8: 11598.71 | I8: 14139.16 | J8: 17304.18
A10: Accumulated Depreciation | B10: 222.27 | C10: 385.08 | D10: 583.52 | E10: 822.92 | F10: 1109.94 | G10: 1434.88 | H10: 1873.1 | I10: 2379.97 | J10: 2954.35
A11: Net Block | B11: =B8-B10 -> 2543.94 | C11: =C8-C10 -> 3276.02 | D11: =D8-D10 -> 4274.03 | E11: =E8-E10 -> 5107.36 | F11: =F8-F10 -> 5938.5 | G11: =G8-G10 -> 7770.46 | H11: =H8-H10 -> 9725.61 | I11: =I8-I10 -> 11759.19 | J11: =J8-J10 -> 14349.83
A13: Change in Gross Block | C13: =C8-B8 -> 894.89 | D13: =D8-C8 -> 1196.45 | E13: =E8-D8 -> 1072.73 | F13: =F8-E8 -> 1118.16 | G13: =G8-F8 -> 2156.9 | H13: =H8-G8 -> 2393.37 | I13: =I8-H8 -> 2540.45 | J13: =J8-I8 -> 3165.02
A14: % Change in Gross Block | C14: =(C8-B8)/C8 -> 0.244432 | D14: =(D8-C8)/D8 -> 0.24630729 | E14: =(E8-D8)/E8 -> 0.18089028 | F14: =(F8-E8)/F8 -> 0.15863936 | G14: =(G8-F8)/G8 -> 0.23430965 | H14: =(H8-G8)/H8 -> 0.20634795 | I14: =(I8-H8)/I8 -> 0.17967475 | J14: =(J8-I8)/J8 -> 0.18290494
A17: Particulars | B17: 42795 | C17: 43160 | D17: 43525 | E17: 43891 | F17: 44256 | G17: 44621 | H17: 44986 | I17: 45352 | J17: 45717
A18: Land | B18: =B2/$B$8 -> 0.37740446 | C18: =C2/$C$8 -> 0.39284914 | D18: =D2/$D$8 -> 0.41753147 | E18: =E2/$E$8 -> 0.38159075 | F18: =F2/$F$8 -> 0.40387093 | G18: =G2/$G$8 -> 0.40097704 | H18: =H2/$H$8 -> 0.3939145 | I18: =I2/$I$8 -> 0.41330037 | J18: =J2/$J$8 -> 0.43508389
A19: Buildings | B19: =B3/$B$8 -> 0.48974951 | C19: =C3/$C$8 -> 0.46930158 | D19: =D3/$D$8 -> 0.43560643 | E19: =E3/$E$8 -> 0.45735952 | F19: =F3/$F$8 -> 0.428963 | G19: =G3/$G$8 -> 0.42823187 | H19: =H3/$H$8 -> 0.43357235 | I19: =I3/$I$8 -> 0.41043103 | J19: =J3/$J$8 -> 0.38232381
A20: Plant & Equipment | B20: =B4/$B$8 -> 0.031845015 | C20: =C4/$C$8 -> 0.033812242 | D20: =D4/$D$8 -> 0.039299647 | E20: =E4/$E$8 -> 0.045915201 | F20: =F4/$F$8 -> 0.048779588 | G20: =G4/$G$8 -> 0.050261044 | H20: =H4/$H$8 -> 0.052998135 | I20: =I4/$I$8 -> 0.058090438 | J20: =J4/$J$8 -> 0.062764604
A21: Furniture & Fixtures | B21: =B5/$B$8 -> 0.039057049 | C21: =C5/$C$8 -> 0.03836825 | D21: =D5/$D$8 -> 0.042336157 | E21: =E5/$E$8 -> 0.045252501 | F21: =F5/$F$8 -> 0.047279965 | G21: =G5/$G$8 -> 0.048166608 | H21: =H5/$H$8 -> 0.046717264 | I21: =I5/$I$8 -> 0.046738279 | J21: =J5/$J$8 -> 0.048265795
A22: Vehicles | B22: =B6/$B$8 -> 0.0022304886 | C22: =C6/$C$8 -> 0.00060364371 | D22: =D6/$D$8 -> 0.00061965394 | E22: =E6/$E$8 -> 0.00060199518 | F22: =F6/$F$8 -> 0.00050791381 | G22: =G6/$G$8 -> 0.00037369614 | H22: =H6/$H$8 -> 0.0012742796 | I22: =I6/$I$8 -> 0.0012249667 | J22: =J6/$J$8 -> 0.00036869704
A23: Other Fixed Assets | B23: =B7/$B$8 -> 0.059713471 | C23: =C7/$C$8 -> 0.065065144 | D23: =D7/$D$8 -> 0.064606643 | E23: =E7/$E$8 -> 0.069280034 | F23: =F7/$F$8 -> 0.070598601 | G23: =G7/$G$8 -> 0.071989736 | H23: =H7/$H$8 -> 0.071523471 | I23: =I7/$I$8 -> 0.070214921 | J23: =J7/$J$8 -> 0.071193203
A24: Gross Block | B24: 1 | C24: 1 | D24: 1 | E24: 1 | F24: 1 | G24: 1 | H24: 1 | I24: 1 | J24: 1
A26: Revenue from Operations | B26: 11898 | C26: 15033 | D26: 20005 | E26: 24870 | F26: 24143 | G26: 30976 | H26: 42840 | I26: 50789 | J26: 59358
A27: Change in Revenue | C27: =C26-B26 -> 3135 | D27: =D26-C26 -> 4972 | E27: =E26-D26 -> 4865 | F27: =F26-E26 -> -727 | G27: =G26-F26 -> 6833 | H27: =H26-G26 -> 11864 | I27: =I26-H26 -> 7949 | J27: =J26-I26 -> 8569
A28: Change in Gross Block | C28: =C8-B8 -> 894.89 | D28: =D8-C8 -> 1196.45 | E28: =E8-D8 -> 1072.73 | F28: =F8-E8 -> 1118.16 | G28: =G8-F8 -> 2156.9 | H28: =H8-G8 -> 2393.37 | I28: =I8-H8 -> 2540.45 | J28: =J8-I8 -> 3165.02
A30: Change in Revenue / Change in Gross Block | C30: =(C27/C28) -> 3.5032239 | D30: =(D27/D28) -> 4.1556271 | E30: =(E27/E28) -> 4.535158 | F30: =(F27/F28) -> -0.65017529 | G30: =(G27/G28) -> 3.1679726 | H30: =(H27/H28) -> 4.9570271 | I30: =(I27/I28) -> 3.1289732 | J30: =(J27/J28) -> 2.7074079
A32: Fixed Asset Turnover Ratio | B32: =B26/'Balance Sheet'!B9 -> 4.6770155 | C32: =C26/'Balance Sheet'!C9 -> 4.5888138 | D32: =D26/'Balance Sheet'!D9 -> 4.6805942 | E32: =E26/'Balance Sheet'!E9 -> 4.8694433 | F32: =F26/'Balance Sheet'!F9 -> 4.0655048 | G32: =G26/'Balance Sheet'!G9 -> 3.9863792 | H32: =H26/'Balance Sheet'!H9 -> 4.4048651 | I32: =I26/'Balance Sheet'!I9 -> 4.31909 | J32: =J26/'Balance Sheet'!J9 -> 4.136495

Sheet Inventory Analysis
A1: Particulars | B1: 43525 | C1: 43891 | D1: 44256 | E1: 44621 | F1: 44986 | G1: 45352 | H1: 45717
A2: Revenue from Operations | B2: 20005 | C2: 24870 | D2: 24143 | E2: 30976 | F2: 42840 | G2: 50789 | H2: 59358
A3: Rev. Growth % | C3: =(C2-B2)/C2 -> 0.19561721 | D3: =(D2-C2)/D2 -> -0.030112248 | E3: =(E2-D2)/E2 -> 0.22059013 | F3: =(F2-E2)/F2 -> 0.27693744 | G3: =(G2-F2)/G2 -> 0.15651027 | H3: =(H2-G2)/H2 -> 0.14436133
A5: Inventory | B5: 1608.65 | C5: 1947.4 | D5: 2248.28 | E5: 2742.66 | F5: 3243.48 | G5: 3927.23 | H5: 5044.37
A6: Inventory Growth % | C6: =(C5-B5)/C5 -> 0.17394988 | D6: =(D5-C5)/D5 -> 0.13382675 | E6: =(E5-D5)/E5 -> 0.18025566 | F6: =(F5-E5)/F5 -> 0.15440823 | G6: =(G5-F5)/G5 -> 0.1741049 | H6: =(H5-G5)/H5 -> 0.22146274
A8: COGS | B8: 17000.84 | C8: 21102.93 | D8: 20554.68 | E8: 26407.39 | F8: 36383.95 | G8: 43274.54 | H8: 50551.7
A9: Inventory as a % of COGS | B9: =B5/B8 -> 0.094621795 | C9: =C5/C8 -> 0.092281024 | D9: =D5/D8 -> 0.10938044 | E9: =E5/E8 -> 0.10385956 | F9: =F5/F8 -> 0.089145901 | G9: =G5/G8 -> 0.090751513 | H9: =H5/H8 -> 0.099786357
A10: Average Inventory | B10: =('Balance Sheet'!C14+'Balance Sheet'!D14)/2 -> 1386.05 | C10: =('Balance Sheet'!D14+'Balance Sheet'!E14)/2 -> 1778.025 | D10: =('Balance Sheet'!E14+'Balance Sheet'!F14)/2 -> 2097.84 | E10: =('Balance Sheet'!F14+'Balance Sheet'!G14)/2 -> 2495.47 | F10: =('Balance Sheet'!G14+'Balance Sheet'!H14)/2 -> 2993.07 | G10: =('Balance Sheet'!H14+'Balance Sheet'!I14)/2 -> 3585.355 | H10: =('Balance Sheet'!I14+'Balance Sheet'!J14)/2 -> 4485.8
A11: Inventory Turnover Ratio | B11: =B8/B10 -> 12.265676 | C11: =C8/C10 -> 11.868748 | D11: =D8/D10 -> 9.7980208 | E11: =E8/E10 -> 10.582131 | F11: =F8/F10 -> 12.156064 | G11: =G8/G10 -> 12.069806 | H11: =H8/H10 -> 11.269272
A12: Inventory Days | B12: =(B10/B8)*365 -> 29.757838 | C12: =(C10/C8)*365 -> 30.753034 | D12: =(D10/D8)*365 -> 37.252421 | E12: =(E10/E8)*365 -> 34.492108 | F12: =(F10/F8)*365 -> 30.026167 | G12: =(G10/G8)*365 -> 30.240751 | H12: =(H10/H8)*365 -> 32.38896
B28: V Mart
B42: Reliance Retail
A43: Particulars | B43: 44256 | C43: 44621 | D43: 44986 | E43: 45352 | F43: 45717 | H43: Year | I43: Revenue from Operations | J43: Rev. Growth % | L43: Inventory | M43: Inventory Growth % | O43: COGS | P43: Inventory as a % of COGS | Q43: Average Inventory | R43: Inventory Turnover Ratio | S43: Inventory Days
A44: Revenue from Operations | B44: 136911 | C44: 170133 | D44: 223653 | E44: 258388 | F44: 271012 | H44: 44256 | I44: 136911 | L44: 12354.79 | O44: 117940.34 | P44: =L44/O44 -> 0.10475457 | Q44: 10851.475 | R44: =O44/Q44 -> 10.8686 | S44: =(Q44/O44)*365 -> 33.582983
A45: Rev. Growth % | C45: =(C44-B44)/C44 -> 0.19527076 | D45: =(D44-C44)/D44 -> 0.23929927 | E45: =(E44-D44)/E44 -> 0.13442962 | F45: =(F44-E44)/F44 -> 0.046580963 | H45: 44621 | I45: 170133 | J45: =(I45-I44)/I45 -> 0.19527076 | L45: 20072.07 | M45: =(L45-L44)/L45 -> 0.38447853 | O45: 147485.2 | P45: =L45/O45 -> 0.13609549 | Q45: =(L44+L45)/2 -> 16213.43 | R45: =O45/Q45 -> 9.0964836 | S45: =(Q45/O45)*365 -> 40.125395
H46: 44986 | I46: 223653 | J46: =(I46-I45)/I46 -> 0.23929927 | L46: 24969 | M46: =(L46-L45)/L46 -> 0.19612039 | O46: 192986 | P46: =L46/O46 -> 0.12938244 | Q46: =(L45+L46)/2 -> 22520.535 | R46: =O46/Q46 -> 8.5693346 | S46: =(Q46/O46)*365 -> 42.593739
A47: Inventory | B47: 12354.79 | C47: 20072.07 | D47: 24969 | E47: 20983 | F47: 18937 | H47: 45352 | I47: 258388 | J47: =(I47-I46)/I47 -> 0.13442962 | L47: 20983 | M47: =(L47-L46)/L47 -> -0.1899633 | O47: 223306 | P47: =L47/O47 -> 0.093965232 | Q47: =(L46+L47)/2 -> 22976 | R47: =O47/Q47 -> 9.7190982 | S47: =(Q47/O47)*365 -> 37.554925
A48: Inventory Growth % | C48: =(C47-B47)/C47 -> 0.38447853 | D48: =(D47-C47)/D47 -> 0.19612039 | E48: =(E47-D47)/E47 -> -0.1899633 | F48: =(F47-E47)/F47 -> -0.10804246 | H48: 45717 | I48: 271012 | J48: =(I48-I47)/I48 -> 0.046580963 | L48: 18937 | M48: =(L48-L47)/L48 -> -0.10804246 | O48: 233997 | P48: =L48/O48 -> 0.080928388 | Q48: =(L47+L48)/2 -> 19960 | R48: =O48/Q48 -> 11.723297 | S48: =(Q48/O48)*365 -> 31.134587
A50: COGS | B50: 117940.34 | C50: 147485.2 | D50: 192986 | E50: 223306 | F50: 233997
A51: Inventory as a % of COGS | B51: =B47/B50 -> 0.10475457 | C51: =C47/C50 -> 0.13609549 | D51: =D47/D50 -> 0.12938244 | E51: =E47/E50 -> 0.093965232 | F51: =F47/F50 -> 0.080928388
A52: Average Inventory | B52: =('Peers-Balance Sheets'!C59+'Peers-Balance Sheets'!B59)/2 -> 10851.475 | C52: =('Peers-Balance Sheets'!D59+'Peers-Balance Sheets'!C59)/2 -> 16213.43 | D52: =('Peers-Balance Sheets'!E59+'Peers-Balance Sheets'!D59)/2 -> 22520.535 | E52: =('Peers-Balance Sheets'!F59+'Peers-Balance Sheets'!E59)/2 -> 22976 | F52: =('Peers-Balance Sheets'!G59+'Peers-Balance Sheets'!F59)/2 -> 19960
A53: Inventory Turnover Ratio | B53: =B50/B52 -> 10.8686 | C53: =C50/C52 -> 9.0964836 | D53: =D50/D52 -> 8.5693346 | E53: =E50/E52 -> 9.7190982 | F53: =F50/F52 -> 11.723297
A54: Inventory Days | B54: =(B52/B50)*365 -> 33.582983 | C54: =(C52/C50)*365 -> 40.125395 | D54: =(D52/D50)*365 -> 42.593739 | E54: =(E52/E50)*365 -> 37.554925 | F54: =(F52/F50)*365 -> 31.134587 | H54: Particulars | I54: Revenue from Operations | J54: Rev. Growth % | L54: Inventory | M54: Inventory Growth % | O54: COGS | P54: Inventory as a % of COGS | Q54: Average Inventory | R54: Inventory Turnover Ratio | S54: Inventory Days
H55: 44256 | I55: 4452.44 | L55: 969.53 | O55: 3225.81 | P55: =L55/O55 -> 0.30055397 | Q55: 1040.725 | R55: =O55/Q55 -> 3.0995796 | S55: =(Q55/O55)*365 -> 117.7579
H56: 44621 | I56: 5588.51 | J56: =(I56-I55)/I56 -> 0.20328674 | L56: 1215.98 | M56: =(L56-L55)/L56 -> 0.20267603 | O56: 4014.61 | P56: =L56/O56 -> 0.3028887 | Q56: =(L55+L56)/2 -> 1092.755 | R56: =O56/Q56 -> 3.6738427 | S56: =(Q56/O56)*365 -> 99.351014
B57: Vishal Mega Marts | H57: 44986 | I57: 7586.04 | J57: =(I57-I56)/I57 -> 0.26331657 | L57: 1409.74 | M57: =(L57-L56)/L57 -> 0.13744378 | O57: 5526.33 | P57: =L57/O57 -> 0.25509515 | Q57: =(L56+L57)/2 -> 1312.86 | R57: =O57/Q57 -> 4.2093826 | S57: =(Q57/O57)*365 -> 86.711054
A58: Particulars | B58: 44256 | C58: 44621 | D58: 44986 | E58: 45352 | F58: 45717 | H58: 45352 | I58: 8911.95 | J58: =(I58-I57)/I58 -> 0.14877889 | L58: 1464.97 | M58: =(L58-L57)/L58 -> 0.037700431 | O58: 6446.06 | P58: =L58/O58 -> 0.22726596 | Q58: =(L57+L58)/2 -> 1437.355 | R58: =O58/Q58 -> 4.484668 | S58: =(Q58/O58)*365 -> 81.38841
A59: Revenue from Operations | B59: 4452.44 | C59: 5588.51 | D59: 7586.04 | E59: 8911.95 | F59: 10716.34 | H59: 45717 | I59: 10716.34 | J59: =(I59-I58)/I59 -> 0.16837745 | L59: 1850.3 | M59: =(L59-L58)/L59 -> 0.20825272 | O59: 7663.62 | P59: =L59/O59 -> 0.24143942 | Q59: =(L58+L59)/2 -> 1657.635 | R59: =O59/Q59 -> 4.6232253 | S59: =(Q59/O59)*365 -> 78.949214
A60: Rev. Growth % | C60: =(C59-B59)/C59 -> 0.20328674 | D60: =(D59-C59)/D59 -> 0.26331657 | E60: =(E59-D59)/E59 -> 0.14877889 | F60: =(F59-E59)/F59 -> 0.16837745
A62: Inventory | B62: 969.53 | C62: 1215.98 | D62: 1409.74 | E62: 1464.97 | F62: 1850.3
A63: Inventory Growth % | C63: =(C62-B62)/C62 -> 0.20267603 | D63: =(D62-C62)/D62 -> 0.13744378 | E63: =(E62-D62)/E62 -> 0.037700431 | F63: =(F62-E62)/F62 -> 0.20825272
A65: COGS | B65: 3225.81 | C65: 4014.61 | D65: 5526.33 | E65: 6446.06 | F65: 7663.62 | H65: Particulars | I65: Revenue from Operations | J65: Rev. Growth % | L65: Inventory | M65: Inventory Growth % | O65: COGS | P65: Inventory as a % of COGS | Q65: Average Inventory | R65: Inventory Turnover Ratio | S65: Inventory Days
A66: Inventory as a % of COGS | B66: =B62/B65 -> 0.30055397 | C66: =C62/C65 -> 0.3028887 | D66: =D62/D65 -> 0.25509515 | E66: =E62/E65 -> 0.22726596 | F66: =F62/F65 -> 0.24143942 | H66: 44256 | I66: 1075.46 | L66: 428.3 | O66: 723.56 | P66: =L66/O66 -> 0.59193432 | Q66: 453.11 | R66: =O66/Q66 -> 1.5968749 | S66: =(Q66/O66)*365 -> 228.57144
A67: Average Inventory | B67: =('Peers-Balance Sheets'!B15+'Peers-Balance Sheets'!C15)/2 -> 1040.725 | C67: =('Peers-Balance Sheets'!C15+'Peers-Balance Sheets'!D15)/2 -> 1092.755 | D67: =('Peers-Balance Sheets'!D15+'Peers-Balance Sheets'!E15)/2 -> 1312.86 | E67: =('Peers-Balance Sheets'!E15+'Peers-Balance Sheets'!F15)/2 -> 1437.355 | F67: =('Peers-Balance Sheets'!F15+'Peers-Balance Sheets'!G15)/2 -> 1657.635 | H67: 44621 | I67: 1666.17 | J67: =(I67-I66)/I67 -> 0.35453165 | L67: 668.22 | M67: =(L67-L66)/L67 -> 0.35904343 | O67: 1091.11 | P67: =L67/O67 -> 0.61242221 | Q67: =(L66+L67)/2 -> 548.26 | R67: =O67/Q67 -> 1.9901324 | S67: =(Q67/O67)*365 -> 183.40488
A68: Inventory Turnover Ratio | B68: =B65/B67 -> 3.0995796 | C68: =C65/C67 -> 3.6738427 | D68: =D65/D67 -> 4.2093826 | E68: =E65/E67 -> 4.484668 | F68: =F65/F67 -> 4.6232253 | H68: 44986 | I68: 2464.83 | J68: =(I68-I67)/I68 -> 0.32402235 | L68: 870.63 | M68: =(L68-L67)/L68 -> 0.23248682 | O68: 1595.09 | P68: =L68/O68 -> 0.54581873 | Q68: =(L67+L68)/2 -> 769.425 | R68: =O68/Q68 -> 2.0730935 | S68: =(Q68/O68)*365 -> 176.06538
A69: Inventory Days | B69: =(B67/B65)*365 -> 117.7579 | C69: =(C67/C65)*365 -> 99.351014 | D69: =(D67/D65)*365 -> 86.711054 | E69: =(E67/E65)*365 -> 81.38841 | F69: =(F67/F65)*365 -> 78.949214 | H69: 45352 | I69: 2785.6 | J69: =(I69-I68)/I69 -> 0.11515293 | L69: 816.07 | M69: =(L69-L68)/L69 -> -0.06685701 | O69: 1825.09 | P69: =L69/O69 -> 0.44713959 | Q69: =(L68+L69)/2 -> 843.35 | R69: =O69/Q69 -> 2.1640956 | S69: =(Q69/O69)*365 -> 168.66168
H70: 45717 | I70: 3253.86 | J70: =(I70-I69)/I70 -> 0.14390908 | L70: 986.83 | M70: =(L70-L69)/L70 -> 0.17303892 | O70: 2129.72 | P70: =L70/O70 -> 0.46336138 | Q70: =(L69+L70)/2 -> 901.45 | R70: =O70/Q70 -> 2.3625492 | S70: =(Q70/O70)*365 -> 154.49414
A72: Particulars | B72: 44256 | C72: 44621 | D72: 44986 | E72: 45352 | F72: 45717
A73: Revenue from Operations | B73: 1075.46 | C73: 1666.17 | D73: 2464.83 | E73: 2785.6 | F73: 3253.86
A74: Rev. Growth % | C74: =(C73-B73)/C73 -> 0.35453165 | D74: =(D73-C73)/D73 -> 0.32402235 | E74: =(E73-D73)/E73 -> 0.11515293 | F74: =(F73-E73)/F73 -> 0.14390908 | H74: Particulars | I74: Avenue Supermarts | J74: Reliance Retail | K74: Vishal Mega Mart | L74: V Mart
...

Sheet Peers-Balance Sheets
B1: Vishal Mega Mart
A2: Particulars | B2: 43891 | C2: 44256 | D2: 44621 | E2: 44986 | F2: 45352 | G2: 45717
A3: Equity Capital | B3: 4365.66 | C3: 4484.12 | D3: 4503.29 | E3: 4506.59 | F3: 4508.72 | G3: 4597.42
A4: Reserves | B4: -93.48 | C4: 104.56 | D4: 321.88 | E4: 649.49 | F4: 1113.11 | G4: 1803.87
A5: Borrowings | B5: 1854.17 | C5: 1139.6 | D5: 1789.32 | E5: 1461.63 | F5: 1483.39 | G5: 1729.34
A6: Trade Payables | B6: 1067.83 | C6: 1275.76 | D6: 1460.62 | E6: 1500.79 | F6: 1220.02 | G6: 1478.56
A7: Other Liabilities | B7: =B8-(SUM(B3:B6)) -> 227.47 | C7: =C8-(SUM(C3:C6)) -> 901.14 | D7: =D8-(SUM(D3:D6)) -> 142.83 | E7: =E8-(SUM(E3:E6)) -> 170.41 | F7: =F8-(SUM(F3:F6)) -> 180.82 | G7: =G8-(SUM(G3:G6)) -> 383.85
A8: Total Liabilities | B8: 7421.65 | C8: 7905.18 | D8: 8217.94 | E8: 8288.91 | F8: 8506.06 | G8: 9993.04
A10: Fixed Assets | B10: 344.45 | C10: 346.7 | D10: 401.75 | E10: 463.09 | F10: 591.85 | G10: 697.05
A11: CWIP | B11: 20.3 | C11: 9.22 | D11: 11.14 | E11: 68.52 | F11: 38.33 | G11: 13.63
A12: Right-of-Use Assets | B12: 934.39 | C12: 972.27 | D12: 1103.04 | E12: 1136.94 | F12: 1299.62 | G12: 1545.65
A13: Other Non-Current Assets | B13: 4300.64 | C13: 4298.58 | D13: 4297.63 | E13: 4292.55 | F13: 4291.8 | G13: 4274.03
A14: Investments | B14: 87.33 | C14: 546.51 | D14: 416.79 | E14: 35.08 | F14: - | G14: 387.2
A15: Inventory | B15: 1111.92 | C15: 969.53 | D15: 1215.98 | E15: 1409.74 | F15: 1464.97 | G15: 1850.3
A16: Trade Receivables | B16: 3.09 | C16: 3.33 | D16: 2.32 | E16: 4.15 | F16: 31.74 | G16: 66.7
A17: Cash & Bank | B17: 115.28 | C17: 278.16 | D17: 214.47 | E17: 169.21 | F17: 118.89 | G17: 463.66
A18: Other Financial Assets | B18: 66.71 | C18: 74.46 | D18: 90.04 | E18: 102.89 | F18: 137.2 | G18: 116.03
A19: Other Assets | B19: =B20-(SUM(B10:B18)) -> 437.54 | C19: =C20-(SUM(C10:C18)) -> 406.42 | D19: =D20-(SUM(D10:D18)) -> 464.78 | E19: =E20-(SUM(E10:E18)) -> 606.74 | F19: =F20-(SUM(F10:F18)) -> 531.66 | G19: =G20-(SUM(G10:G18)) -> 578.79
A20: Total Assets | B20: 7421.65 | C20: 7905.18 | D20: 8217.94 | E20: 8288.91 | F20: 8506.06 | G20: 9993.04
B23: V Mart
A24: Particulars | B24: 43891 | C24: 44256 | D24: 44621 | E24: 44986 | F24: 45352 | G24: 45717
A25: Equity Capital | B25: 18.15 | C25: 19.7 | D25: 19.74 | E25: 19.77 | F25: 19.78 | G25: 19.8
A26: Reserves | B26: 440.77 | C26: 805.52 | D26: 829.86 | E26: 829.23 | F26: 727.21 | G26: 790.38
A27: Borrowings | B27: =437.83+6.12+1.04+77.82 -> 522.81 | C27: =530.78+37.01 -> 567.79 | D27: =842.93+59.26 -> 902.19 | E27: =1107.73+76.1 -> 1183.83 | F27: =1193.54+110+87.71 -> 1391.25 | G27: =440.97+148.96 -> 589.93
A28: Trade Payables | B28: =50.43+146.35 -> 196.78 | C28: =55.88+135.79 -> 191.67 | D28: =61.34+229.23 -> 290.57 | E28: =149.79+338.54 -> 488.33 | F28: =196.74+436.92 -> 633.66 | G28: =192.12+569.86 -> 761.98
A29: Other Liabilities | B29: =B30-(SUM(B25:B28)) -> 45.13 | C29: =C30-(SUM(C25:C28)) -> 41.86 | D29: =D30-(SUM(D25:D28)) -> 57.12 | E29: =E30-(SUM(E25:E28)) -> 221.37 | F29: =F30-(SUM(F25:F28)) -> 73.43 | G29: =G30-(SUM(G25:G28)) -> 274.15
A30: Total Liabilities | B30: 1223.64 | C30: 1626.54 | D30: 2099.48 | E30: 2742.53 | F30: 2845.33 | G30: 2436.24
A32: Fixed Assets | B32: 171.27 | C32: 175.78 | D32: 279.49 | E32: 319.11 | F32: 489.8 | G32: 527.41
A33: CWIP | B33: 2.46 | C33: 2.19 | D33: 6.37 | E33: 109.24 | F33: 3.84 | G33: 4.31
A34: Right-of-Use Assets | B34: 492.11 | C34: 517.99 | D34: 828.27 | E34: 1064.26 | F34: 1119.65 | G34: 469.88
A35: Other Non-Current Assets | B35: 3.65 | C35: 2.75 | D35: 3.2 | E35: =1.5+60.59 -> 62.09 | F35: =1.5+49.79 -> 51.29 | G35: =1.5+39.73 -> 41.23
A36: Investments | B36: =3.31+4.57 -> 7.88 | C36: =3.61+315.36 -> 318.97 | D36: =3.78+121.06 -> 124.84 | E36: 8.54 | F36: 4.7 | G36: 5.05
A37: Inventory | B37: 477.92 | C37: 428.3 | D37: 668.22 | E37: 870.63 | F37: 816.07 | G37: 986.83
A38: Trade Receivables | B38: - | C38: - | D38: - | E38: - | F38: - | G38: -
A39: Cash & Bank | B39: =4.89+0.09 -> 4.98 | C39: =23.79+3.67 -> 27.46 | D39: =33.03+2.02 -> 35.05 | E39: 18.06 | F39: 27.23 | G39: 39.42
A40: Other Financial Assets | B40: =70.49+1.43 -> 71.92 | C40: =70.96+14.26 -> 85.22 | D40: =36.98+0.18 -> 37.16 | E40: =26.95+32.12 -> 59.07 | F40: =26.14+47.44 -> 73.58 | G40: =39.97+46.18 -> 86.15
A41: Other Assets | B41: =B42-SUM(B32:B40) -> -8.55 | C41: =C42-SUM(C32:C40) -> 67.88 | D41: =D42-SUM(D32:D40) -> 116.88 | E41: =E42-SUM(E32:E40) -> 231.53 | F41: =F42-SUM(F32:F40) -> 259.17 | G41: =G42-SUM(G32:G40) -> 275.96
A42: Total Assets | B42: 1223.64 | C42: 1626.54 | D42: 2099.48 | E42: 2742.53 | F42: 2845.33 | G42: 2436.24
B45: Reliance Retail
A46: Particulars | B46: 43891 | C46: 44256 | D46: 44621 | E46: 44986 | F46: 45352 | G46: 45717
...

Sheet Trade Payables Analysis
A1: Particulars | B1: 43525 | C1: 43891 | D1: 44256 | E1: 44621 | F1: 44986 | G1: 45352 | H1: 45717
A2: Revenue from Operations | B2: 20005 | C2: 24870 | D2: 24143 | E2: 30976 | F2: 42840 | G2: 50789 | H2: 59358
A3: YoY Growth (%) | C3: =((C2-B2)/C2) -> 0.19561721 | D3: =((D2-C2)/D2) -> -0.030112248 | E3: =((E2-D2)/E2) -> 0.22059013 | F3: =((F2-E2)/F2) -> 0.27693744 | G3: =((G2-F2)/G2) -> 0.15651027 | H3: =((H2-G2)/H2) -> 0.14436133
A5: Trade Payables | B5: 463.27 | C5: 433.45 | D5: 578.13 | E5: 589.2 | F5: 753.79 | G5: 984.81 | H5: 1070.81
A6: Payables Growth % | C6: =(C5-B5)/C5 -> -0.068796862 | D6: =(D5-C5)/D5 -> 0.25025513 | E6: =(E5-D5)/E5 -> 0.018788187 | F6: =(F5-E5)/F5 -> 0.21834994 | G6: =(G5-F5)/G5 -> 0.23458332 | H6: =(H5-G5)/H5 -> 0.080313034
A8: COGS | B8: 17000.84 | C8: 21102.93 | D8: 20554.68 | E8: 26407.39 | F8: 36383.95 | G8: 43274.54 | H8: 50551.7
A9: Payables as a % of Rev. | B9: =B5/B2 -> 0.023157711 | C9: =C5/C2 -> 0.017428629 | D9: =D5/D2 -> 0.023946071 | E9: =E5/E2 -> 0.019021178 | F9: =F5/F2 -> 0.017595472 | G9: =G5/G2 -> 0.019390222 | H9: =H5/H2 -> 0.01803986
A10: Payables as a % of COGS | B10: =B5/B8 -> 0.02724983 | C10: =C5/C8 -> 0.020539802 | D10: =D5/D8 -> 0.028126441 | E10: =E5/E8 -> 0.022311936 | F10: =F5/F8 -> 0.020717652 | G10: =G5/G8 -> 0.022757261 | H10: =H5/H8 -> 0.021182473
A12: Average Payables | C12: =(C5+B5)/2 -> 448.36 | D12: =(D5+C5)/2 -> 505.79 | E12: =(E5+D5)/2 -> 583.665 | F12: =(F5+E5)/2 -> 671.495 | G12: =(G5+F5)/2 -> 869.3 | H12: =(H5+G5)/2 -> 1027.81
A13: Payable Turnover Ratio | C13: =M12/C12 -> 0 | D13: =N12/D12 -> 0 | E13: =O12/E12 -> 0 | F13: =P12/F12 -> 0 | G13: =Q12/G12 -> 0 | H13: =R12/H12 -> 0
A14: Payable Days | C14: =(C12/C8)*365 -> 7.7549137 | D14: =(D12/D8)*365 -> 8.9815726 | E14: =(E12/E8)*365 -> 8.0673525 | F14: =(F12/F8)*365 -> 6.736368 | G14: =(G12/G8)*365 -> 7.3321288 | H14: =(H12/H8)*365 -> 7.4211283
B31: Reliance Retail
A32: Particulars | B32: 44256 | C32: 44621 | D32: 44986 | E32: 45352 | F32: 45717
A33: Revenue from Operations | B33: 136911 | C33: 170133 | D33: 223653 | E33: 258388 | F33: 271012
A34: YoY Growth (%) | C34: =(C33-B33)/C33 -> 0.19527076 | D34: =(D33-C33)/D33 -> 0.23929927 | E34: =(E33-D33)/E33 -> 0.13442962 | F34: =(F33-E33)/F33 -> 0.046580963
A36: Trade Payables | B36: 6705.53 | C36: 12990.01 | D36: =971+14518 -> 15489 | E36: =667+23079 -> 23746 | F36: =284+19223 -> 19507
A37: Payables Growth % | C37: =(C36-B36)/C36 -> 0.48379332 | D37: =(D36-C36)/D36 -> 0.16133966 | E37: =(E36-D36)/E36 -> 0.34772172 | F37: =(F36-E36)/F36 -> -0.21730661
A39: COGS | B39: 117940.34 | C39: 147485.2 | D39: 192986 | E39: 223306 | F39: 233997
A40: Payables as a % of Rev. | B40: =B36/B33 -> 0.048977292 | C40: =C36/C33 -> 0.076352089 | D40: =D36/D33 -> 0.069254604 | E40: =E36/E33 -> 0.091900553 | F40: =F36/F33 -> 0.071978363
